Exception in thread Thread-1 (forward_packets):
Traceback (most recent call last):
Exception in thread Thread-2 (forward_packets):
Traceback (most recent call last):
  File "/usr/lib/python3.11/threading.py", line 1038, in _bootstrap_inner
  File "/usr/lib/python3.11/threading.py", line 1038, in _bootstrap_inner
    self.run()
  File "/usr/lib/python3.11/threading.py", line 975, in run
    self.run()
    self._target(*self._args, **self._kwargs)
  File "/usr/lib/python3.11/threading.py", line 975, in run
  File "/home/jason/projects/cs118_proj2/rdcc_proxy.py", line 96, in forward_packets
    self._target(*self._args, **self._kwargs)
  File "/home/jason/projects/cs118_proj2/rdcc_proxy.py", line 96, in forward_packets
    s.bind(('localhost', listen_port))
OSError: [Errno 98] Address already in use
    s.bind(('localhost', listen_port))
OSError: [Errno 98] Address already in use
Exception in thread Thread-2 (forward_packets):
Traceback (most recent call last):
  File "/usr/lib/python3.11/threading.py", line 1038, in _bootstrap_inner
Exception in thread Thread-1 (forward_packets):
Traceback (most recent call last):
    self.run()
  File "/usr/lib/python3.11/threading.py", line 1038, in _bootstrap_inner
  File "/usr/lib/python3.11/threading.py", line 975, in run
    self.run()
    self._target(*self._args, **self._kwargs)
  File "/usr/lib/python3.11/threading.py", line 975, in run
  File "/home/jason/projects/cs118_proj2/rdcc_proxy.py", line 96, in forward_packets
    self._target(*self._args, **self._kwargs)
  File "/home/jason/projects/cs118_proj2/rdcc_proxy.py", line 96, in forward_packets
    s.bind(('localhost', listen_port))
OSError: [Errno 98] Address already in use
    s.bind(('localhost', listen_port))
OSError: [Errno 98] Address already in use
